Workbook
Name Slicer_Admission_Type: #N/A
Name Slicer_Age: #N/A
Name Slicer_Department1: #N/A
Name Slicer_Department2: #N/A
Name Slicer_Doctor: #N/A
Name Slicer_Gender: #N/A
Name Slicer_Gender1: #N/A
Name Slicer_Insurance1: #N/A
Name Slicer_Insurance2: #N/A
Name Slicer_Length_of_Stay: #N/A
Name Slicer_Patient_ID: #N/A
Name Slicer_Satisfaction_Score: #N/A
Name Slicer_Treatment_Cost: #N/A

Sheet  pivot
M1: Row Labels | N1: Average of Treatment_Cost
M2: Cardiology | N2: 54085.682
A3: Row Labels | B3: Count of Patient_ID | M3: Dermatology | N3: 51216.6
A4: Cardiology | B4: 519 | M4: ENT | N4: 51903.126
A5: Dermatology | B5: 493 | M5: Gastroenterology | N5: 53838.256
A6: ENT | B6: 485 | M6: General Medicine | N6: 51852.667
A7: Gastroenterology | B7: 485 | M7: Gynecology | N7: 53367.659
A8: General Medicine | B8: 483 | M8: Neurology | N8: 55186.181
A9: Gynecology | B9: 528 | M9: Oncology | N9: 52920.139
A10: Neurology | B10: 487 | M10: Orthopedics | N10: 53658.631
A11: Oncology | B11: 509 | M11: Pediatrics | N11: 52825.05
A12: Orthopedics | B12: 510 | M12: Grand Total | N12: 53094.212
A13: Pediatrics | B13: 501
A14: Grand Total | B14: 5000
A19: Row Labels | B19: Count of Patient_ID
A20: Emergency | B20: 1709 | M20: Row Labels | N20: Count of Doctor
A21: Referral | B21: 1674 | M21: Cardiology | N21: 519
A22: Scheduled | B22: 1617 | M22: Dermatology | N22: 493
A23: Grand Total | B23: 5000 | M23: ENT | N23: 485
M24: Gastroenterology | N24: 485
M25: General Medicine | N25: 483
M26: Gynecology | N26: 528
M27: Neurology | N27: 487
M28: Oncology | N28: 509
M29: Orthopedics | N29: 510
M30: Pediatrics | N30: 501
M31: Grand Total | N31: 5000
A38: Row Labels | B38: Count of Patient_ID
A39: 0-17 | B39: 960
A40: 18-35 | B40: 928
A41: 36-53 | B41: 1018
A42: 54-71 | B42: 1040
A43: 72-89 | B43: 988
A44: 90-107 | B44: 66
A45: Grand Total | B45: 5000
A48: Row Labels | B48: Sum of Treatment_Cost | C48: Sum of Treatment_Cost2
A49: Cardiology | B49: 28070469 | C49: 28070469
A50: Dermatology | B50: 25249784 | C50: 25249784
A51: ENT | B51: 25173016 | C51: 25173016
A52: Gastroenterology | B52: 26111554 | C52: 26111554
...

Sheet data
A1: Patient_ID | B1: Age | C1: Gender | D1: Department | E1: Doctor | F1: Admission_Type | G1: Length_of_Stay | H1: Treatment_Cost | I1: Insurance | J1: Satisfaction_Score
A2: P0001 | B2: 43 | C2: Male | D2: Gastroenterology | E2: Dr. Priya | F2: Referral | G2: 5 | H2: 95516 | I2: No | J2: 3
A3: P0002 | B3: 62 | C3: Male | D3: Orthopedics | E3: Dr. Kumar | F3: Scheduled | G3: 11 | H3: 64012 | I3: No | J3: 2
A4: P0003 | B4: 79 | C4: Female | D4: Cardiology | E4: Dr. Priya | F4: Emergency | G4: 2 | H4: 83259 | I4: Yes | J4: 2
A5: P0004 | B5: 61 | C5: Male | D5: Cardiology | E5: Dr. Kumar | F5: Referral | G5: 15 | H5: 68126 | I5: No | J5: 4
A6: P0005 | B6: 16 | C6: Female | D6: Gynecology | E6: Dr. Sharma | F6: Emergency | G6: 14 | H6: 80819 | I6: Yes | J6: 2
A7: P0006 | B7: 42 | C7: Male | D7: Pediatrics | E7: Dr. Mehta | F7: Emergency | G7: 7 | H7: 91234 | I7: No | J7: 3
A8: P0007 | B8: 25 | C8: Female | D8: ENT | E8: Dr. Sharma | F8: Emergency | G8: 8 | H8: 12298 | I8: Yes | J8: 5
A9: P0008 | B9: 1 | C9: Female | D9: Dermatology | E9: Dr. Gupta | F9: Scheduled | G9: 6 | H9: 9557 | I9: No | J9: 5
A10: P0009 | B10: 58 | C10: Female | D10: Pediatrics | E10: Dr. Rao | F10: Referral | G10: 13 | H10: 70680 | I10: No | J10: 2
A11: P0010 | B11: 50 | C11: Female | D11: Dermatology | E11: Dr. Priya | F11: Scheduled | G11: 6 | H11: 55506 | I11: No | J11: 1
A12: P0011 | B12: 61 | C12: Female | D12: Oncology | E12: Dr. Sharma | F12: Referral | G12: 7 | H12: 71020 | I12: Yes | J12: 2
A13: P0012 | B13: 8 | C13: Male | D13: Gynecology | E13: Dr. Patel | F13: Referral | G13: 2 | H13: 27439 | I13: No | J13: 5
... A5001: P5000 | B5001: 88 | C5001: Male | D5001: Dermatology | E5001: Dr. Gupta | F5001: Referral | G5001: 9 | H5001: 9267 | I5001: Yes | J5001: 5

Sheet KPI_
A1: KPI Name | B1: Value | C1: Function Applied
A2: Total Patients? =COUNTA(Sheet1!A2:A5001) | B2: =COUNTA(data!A2:A5001) -> 5000 | C2: COUNTA
A3: Total Treatment Cost ? =SUM(Sheet1!H2:H5001) | B3: =SUM(data!H2:H5001) -> 265471058 | C3: SUM(
A4: Average Treatment Cost ? =AVERAGE(Sheet1!H2:H5001) | B4: =AVERAGE(data!H2:H5001) -> 53094.212 | C4: AVERAGE
A5: Average Length of Stay ? =AVERAGE(Sheet1!G2:G5001) | B5: =AVERAGE(data!G2:G5001) -> 7.9398 | C5: AVERAGE
A6: Insurance Coverage % ? =COUNTIF(Sheet1!I:I,"Yes")/COUNTA(Sheet1!A2:A5001) | B6: =COUNTIF(data!I:I,"No") -> 2481 | C6: COUNTIF
A7: Avg Satisfaction Score ? =AVERAGE(Sheet1!J2:J5001) | B7: =AVERAGE(data!J2:J5001) -> 2.9882 | C7: AVERAGE

Sheet Analysis
A1: Analysis Point | B1: Value
A2: Total Gastroenterology Patients | B2: =COUNTIF(data!D:D,"Gastroenterology") -> 485
A3: Total Cardiology Patients | B3: =COUNTIF(data!D:D,"Orthopedics") -> 510
A4: Total Gynecology Patients | B4: =COUNTIF(data!D:D,"Pediatrics") -> 501
A5: Total Pediatrics Patients | B5: =COUNTIF(data!D:D,"ENT") -> 485
A6: Total ENT Patients | B6: =COUNTIF(data!D:D,"Dermatology") -> 493
A7: Total Dermatology Patients | B7: =COUNTIF(data!D:D,"Dermatology") -> 493
A8: Total Oncology Patients | B8: =COUNTIF(data!D:D,"Oncology") -> 509
A9: Total General Medicine Patients | B9: =COUNTIF(data!D:D,"General Medicine") -> 483
A10: Total Neurology Patients | B10: =COUNTIF(data!D:D,"Neurology") -> 487
A11: Insurance - Yes | B11: =COUNTIF(data!I:I,"Yes") -> 2519
A12: Insurance - No | B12: =COUNTIF(data!I:I,"No") -> 2481
A13: Avg Cost - Gastroenterology | B13: =AVERAGEIF(data!D:D,"Gastroenterology",data!H:H) -> 53838.256
A14: Avg Cost - Orthopedics | B14: =AVERAGEIF(data!D:D,"Orthopedics",data!H:H) -> 53658.631
A15: Avg Cost - Cardiology | B15: =AVERAGEIF(data!D:D,"Cardiology",data!H:H) -> 54085.682
A16: Highest Treatment Cost | B16: =MAX(data!H:H) -> 99997
A17: Lowest Treatment Cost | B17: =MIN(data!H:H) -> 5031

Sheet Dashboard
A1: Hospital Performance & Patient Insights Dashboard
B4: TOTAL PATIENTS | E4: TOTAL TREATMENT COST | I4: AVERAGE LENGTH OF STAY | M4: INSURANCE COVERAGE | Q4: AVERAGE TREATMENT COST
B5: 5000 | E5: 26547K | I5: 8 DAYS | M5: 0.496 | Q5: 53K
A8: 1.Department-wise Patient Count | I8: 2.Revenue by Department
A27: 3.Doctor Count by Department | I27: 4.Gender Distribution
A48: 5.Admission type Distribution
A68: 6.Patients Distribution by Age Group
A89: 7.Average Treatment Cost by Department
